<mujoco model="franka_base">
  <compiler angle="radian" meshdir="./assets"/>

  <option integrator="implicitfast"/>

  <default>
    <default class="visual">
      <geom type="mesh" contype="0" conaffinity="0" group="2"/>
    </default>
    <default class="collision">
      <geom type="mesh" group="3"/>
    </default>
  </default>

  <asset>
    <material name="gray" rgba="0.62745098 0.65098039 0.64705882 1"/>
    <mesh file="base.stl"/>
  </asset>


  <worldbody>
    <body name="base_link">
      <inertial pos="0 0 0" mass="60" diaginertia="0.001 0.001 0.001"/>
      <joint name="joint_x"  type="slide" axis="1 0 0"/>
      <joint name="joint_y"  type="slide" axis="0 1 0"/>
      <joint name="joint_th" type="hinge" axis="0 0 1"/>
      <geom class="visual" mesh="base" material="gray"/>
      <geom class="collision" mesh="base"/>
    </body>
  </worldbody>

  <actuator>
    <position name="joint_x"  joint="joint_x"  kp="1000000" kv="50000"/>
    <position name="joint_y"  joint="joint_y"  kp="1000000" kv="50000"/>
    <position name="joint_th" joint="joint_th" kp="50000"   kv="1000"/>
  </actuator>
</mujoco>
